Workbook

Sheet 汇率
A1: 汇率 | C1: 更新时间 4-30
A2: USD-CNY | B2: 6.8628
A3: €-CNY | B3: 8.0057
A5: 中信保 | B5: 0.00163
A7: USD-泰铢 | B7: 32.05
A8: USD-马币 | B8: 3.9855
A9: USD-越南盾 | B9: 26321
A11: USD-EUR | B11: 0.8527

Sheet 逆变器-硕日
A1: 产品信息 | F1: 装箱情况 | I1: FOB市场定价$ | M1: FOB市场定价€ | Q1: 市场定价欧仓提货价$ | U1: 市场定价欧仓提货价€
A2: 厂家 | B2: 分类 | C2: 物料编码 | D2: 产品型号 | E2: 规格 | F2: 装柜量 | G2: 单托数量 | H2: 托盘数 | I2: 大型经销商 | J2: 中型经销商 | K2: 中型安装商 | L2: 小型安装商 | M2: 大型经销商 | N2: 中型经销商 | O2: 中型安装商 | P2: 小型安装商 | Q2: 大型经销商 | R2: 中型经销商 | S2: 中型安装商 | T2: 小型安装商 | U2: 大型经销商 | V2: 中型经销商 | W2: 中型安装商 | X2: 小型安装商
A3: 硕日 | B3: Low voltage Single phase 低压单相逆变器 | C3: N036101-000091-001 | D3: SWH3600L-S1-SR | E3: 3.6kw | F3: 672 | G3: 16 | H3: 42 | I3: 484.58 | J3: 502.7 | K3: 520.81 | L3: 566.1 | M3: 410.88 | N3: 426.24 | O3: 441.6 | P3: 480 | Q3: 499.44 | R3: 518.11 | S3: 536.78 | T3: 583.45 | U3: 423.47 | V3: 439.3 | W3: 455.13 | X3: 494.71
C4: N036101-000092-001 | D4: SWH4000L-S1-SR | E4: 4kw | F4: 672 | G4: 16 | H4: 42 | I4: 484.58 | J4: 502.7 | K4: 520.81 | L4: 566.1 | M4: 410.88 | N4: 426.24 | O4: 441.6 | P4: 480 | Q4: 499.44 | R4: 518.11 | S4: 536.78 | T4: 583.45 | U4: 423.47 | V4: 439.3 | W4: 455.13 | X4: 494.71
C5: N036101-000006-005 | D5: SWH5000L-S1-SR | E5: 5kw | F5: 672 | G5: 16 | H5: 42 | I5: 484.58 | J5: 502.7 | K5: 520.81 | L5: 566.1 | M5: 410.88 | N5: 426.24 | O5: 441.6 | P5: 480 | Q5: 499.44 | R5: 518.11 | S5: 536.78 | T5: 583.45 | U5: 423.47 | V5: 439.3 | W5: 455.13 | X5: 494.71
C6: N036101-000017-003 | D6: SWH6000L-S1-SR | E6: 6kw | F6: 672 | G6: 16 | H6: 42 | I6: 484.58 | J6: 502.7 | K6: 520.81 | L6: 566.1 | M6: 410.88 | N6: 426.24 | O6: 441.6 | P6: 480 | Q6: 499.44 | R6: 518.11 | S6: 536.78 | T6: 583.45 | U6: 423.47 | V6: 439.3 | W6: 455.13 | X6: 494.71
C7: N036101-000007-004 | D7: SWH008KL-S1-SR | E7: 8kw | F7: 252 | G7: 12 | H7: 21 | I7: 1011.21 | J7: 1049.01 | K7: 1086.81 | L7: 1181.32 | M7: 857.4 | N7: 889.45 | O7: 921.51 | P7: 1001.64 | Q7: 1044.6 | R7: 1083.65 | S7: 1122.7 | T7: 1220.32 | U7: 885.71 | V7: 918.83 | W7: 951.94 | X7: 1034.71
C8: N036101-000008-007 | D8: SWH010KL-S1-SR | E8: 10kw | F8: 252 | G8: 12 | H8: 21 | I8: 1011.21 | J8: 1049.01 | K8: 1086.81 | L8: 1181.32 | M8: 857.4 | N8: 889.45 | O8: 921.51 | P8: 1001.64 | Q8: 1044.6 | R8: 1083.65 | S8: 1122.7 | T8: 1220.32 | U8: 885.71 | V8: 918.83 | W8: 951.94 | X8: 1034.71
C9: N036101-000016-003 | D9: SWH012KL-S1-SR | E9: 12kw | F9: 252 | G9: 12 | H9: 21 | I9: 1011.21 | J9: 1049.01 | K9: 1086.81 | L9: 1181.32 | M9: 857.4 | N9: 889.45 | O9: 921.51 | P9: 1001.64 | Q9: 1044.6 | R9: 1083.65 | S9: 1122.7 | T9: 1220.32 | U9: 885.71 | V9: 918.83 | W9: 951.94 | X9: 1034.71
B10: LV Battery 5.12KWh Rack 低压电池机架式 | C10: N030502-000034-000 | D10: 低压电池 SWR5.12-L1-SR | E10: 5.12kWh 机架式 | F10: 576 | G10: 12 | H10: 48 | I10: 548.44 | J10: 568.94 | K10: 589.45 | L10: 640.7 | M10: 465.02 | N10: 482.41 | O10: 499.79 | P10: 543.25 | Q10: 582.76 | R10: 604.55 | S10: 626.33 | T10: 680.8 | U10: 494.13 | V10: 512.6 | W10: 531.07 | X10: 577.25
B11: LV Battery 5.12Kwh Wall 低压壁挂电池 | C11: N030502-000036-000 | D11: 低压电池 SWR5.12-L1-SW | E11: 5.12kWh壁挂式 | F11: 416 | G11: 8 | H11: 52 | I11: 696.82 | J11: 722.87 | K11: 748.91 | L11: 814.04 | M11: 590.83 | N11: 612.92 | O11: 635 | P11: 690.22 | Q11: 742.17 | R11: 769.92 | S11: 797.66 | T11: 867.02 | U11: 629.29 | V11: 652.81 | W11: 676.34 | X11: 735.15
B12: LV Battery 10.24KWh Wall低压壁挂电池 | C12: N030502-000038-000 | D12: 低压电池 SWR10.24-L1-SW | E12: 10.24kWh壁挂式 | F12: 256 | G12: 4 | H12: 64 | I12: 1481.68 | J12: 1537.07 | K12: 1592.46 | L12: 1730.94 | M12: 1256.32 | N12: 1303.28 | O12: 1350.25 | P12: 1467.66 | Q12: 1570.48 | R12: 1629.19 | S12: 1687.9 | T12: 1834.68 | U12: 1331.61 | V12: 1381.39 | W12: 1431.17 | X12: 1555.62
B13: 16.07kWh低压壁挂电池 (51.2V, 314Ah, IP30) | C13: N030502-000044-000 | D13: SWR16.07-L2-SW | E13: 16.07kWh壁挂式 | F13: 240 | G13: 1 | H13: 240 | I13: 1407.94 | J13: 1460.57 | K13: 1513.21 | L13: 1644.79 | M13: 1193.79 | N13: 1238.42 | O13: 1283.05 | P13: 1394.62 | Q13: 1521.58 | R13: 1578.46 | S13: 1635.34 | T13: 1777.54 | U13: 1290.15 | V13: 1338.38 | W13: 1386.6 | X13: 1507.18
B14: （低压电池）IP30 | D14: SWR5.12-L1-SW | E14: 5.12kWh | F14: 368 | G14: 8 | H14: 46 | I14: 563.96 | J14: 585.05 | K14: 606.13 | L14: 658.84 | M14: 478.19 | N14: 496.06 | O14: 513.94 | P14: 558.63 | Q14: 605.95 | R14: 628.6 | S14: 651.25 | T14: 707.88 | U14: 513.78 | V14: 532.99 | W14: 552.2 | X14: 600.21
D15: SWR10.24-L1-SW | E15: 10.24kWh | F15: 264 | G15: 4 | H15: 66 | I15: 993.61 | J15: 1030.75 | K15: 1067.89 | L15: 1160.75 | M15: 842.48 | N15: 873.97 | O15: 905.47 | P15: 984.2 | Q15: 1062.76 | R15: 1102.49 | S15: 1142.22 | T15: 1241.55 | U15: 901.12 | V15: 934.8 | W15: 968.49 | X15: 1052.71
B16: 三相低压逆变器 | D16: SPI-8K-H3P | E16: 8kw | F16: 322 | G16: 7 | H16: 46 | I16: 1024.52 | J16: 1062.82 | K16: 1101.12 | L16: 1196.87 | M16: 868.69 | N16: 901.16 | O16: 933.64 | P16: 1014.82 | Q16: 1055.86 | R16: 1095.33 | S16: 1134.81 | T16: 1233.48 | U16: 895.27 | V16: 928.73 | W16: 962.2 | X16: 1045.87
D17: SPI-10K-H4P | E17: 10kw | F17: 322 | G17: 7 | H17: 46 | I17: 1024.52 | J17: 1062.82 | K17: 1101.12 | L17: 1196.87 | M17: 868.69 | N17: 901.16 | O17: 933.64 | P17: 1014.82 | Q17: 1055.86 | R17: 1095.33 | S17: 1134.81 | T17: 1233.48 | U17: 895.27 | V17: 928.73 | W17: 962.2 | X17: 1045.87
D18: SPI-12K-H5P | E18: 12kw | F18: 322 | G18: 7 | H18: 46 | I18: 1024.52 | J18: 1062.82 | K18: 1101.12 | L18: 1196.87 | M18: 868.69 | N18: 901.16 | O18: 933.64 | P18: 1014.82 | Q18: 1055.86 | R18: 1095.33 | S18: 1134.81 | T18: 1233.48 | U18: 895.27 | V18: 928.73 | W18: 962.2 | X18: 1045.87

Sheet 逆变器-固德威
A1: 产品信息 | F1: 装箱情况 | I1: FOB市场定价$ | M1: FOB市场定价€ | Q1: 市场定价欧仓提货价$ | U1: 市场定价欧仓提货价€
A2: 厂家 | B2: 分类 | C2: 产品型号 | D2: 创维型号 | E2: 规格 | F2: 装柜量 | G2: 单托数量 | H2: 托盘数 | I2: 大型经销商 | J2: 中型经销商 | K2: 中型安装商 | L2: 小型安装商 | M2: 大型经销商 | N2: 中型经销商 | O2: 中型安装商 | P2: 小型安装商 | Q2: 大型经销商 | R2: 中型经销商 | S2: 中型安装商 | T2: 小型安装商 | U2: 大型经销商 | V2: 中型经销商 | W2: 中型安装商 | X2: 小型安装商
A3: 固德威（东南亚） | B3: 单相低压储能逆变器 | C3: GW3000-ES-C10 | D3: SWH3000L-S1-G2 | E3: 3KW | F3: 336 | G3: 6 | H3: 56 | I3: 477.81 | J3: 490.84 | K3: 512.56 | L3: 556 | M3: 405.14 | N3: 416.18 | O3: 434.6 | P3: 471.43 | Q3: 514.99 | R3: 529.03 | S3: 552.44 | T3: 599.26 | U3: 436.66 | V3: 448.57 | W3: 468.42 | X3: 508.11
C4: GW3600-ES-C10 | D4: SWH3600L-S1-G2 | E4: 3.6kW | F4: 336 | G4: 6 | H4: 56 | I4: 525.58 | J4: 539.91 | K4: 563.8 | L4: 611.58 | M4: 445.64 | N4: 457.79 | O4: 478.05 | P4: 518.56 | Q4: 564.17 | R4: 579.56 | S4: 605.2 | T4: 656.49 | U4: 478.36 | V4: 491.41 | W4: 513.15 | X4: 556.64
C5: GW5000-ES-C10 | D5: SWH5000L-S1-G2 | E5: 5KW | F5: 336 | G5: 6 | H5: 56 | I5: 549.96 | J5: 564.96 | K5: 589.95 | L5: 639.95 | M5: 466.31 | N5: 479.03 | O5: 500.22 | P5: 542.61 | Q5: 589.27 | R5: 605.34 | S5: 632.13 | T5: 685.7 | U5: 499.64 | V5: 513.27 | W5: 535.98 | X5: 581.4
C6: GW6000-ES-C10 | D6: SWH6000L-S1-G2 | E6: 6k | F6: 336 | G6: 6 | H6: 56 | I6: 570.25 | J6: 585.8 | K6: 611.72 | L6: 663.56 | M6: 483.51 | N6: 496.7 | O6: 518.68 | P6: 562.63 | Q6: 610.17 | R6: 626.81 | S6: 654.54 | T6: 710.01 | U6: 517.36 | V6: 531.47 | W6: 554.99 | X6: 602.02
C7: GW8000-ES-C10 | D7: SWH8000L-S1-G2 | E7: 8k | F7: 384 | G7: 12 | H7: 32 | I7: 737.99 | J7: 758.12 | K7: 791.67 | L7: 858.76 | M7: 625.74 | N7: 642.81 | O7: 671.25 | P7: 728.14 | Q7: 777.97 | R7: 799.18 | S7: 834.55 | T7: 905.27 | U7: 659.64 | V7: 677.63 | W7: 707.61 | X7: 767.58
C8: GW10K-ES-C10 | D8: SWH010KL-S1-G2 | E8: 10k | F8: 192 | G8: 6 | H8: 32 | I8: 846.1 | J8: 869.18 | K8: 907.64 | L8: 984.55 | M8: 717.41 | N8: 736.98 | O8: 769.58 | P8: 834.8 | Q8: 907.21 | R8: 931.95 | S8: 973.19 | T8: 1055.66 | U8: 769.22 | V8: 790.2 | W8: 825.17 | X8: 895.1
C9: GW12K-ES-C10 | D9: SWH012KL-S1-G2 | E9: 12k | F9: 264 | G9: 6 | H9: 44 | I9: 876.52 | J9: 900.43 | K9: 940.27 | L9: 1019.95 | M9: 743.2 | N9: 763.47 | O9: 797.26 | P9: 864.82 | Q9: 930.24 | R9: 955.61 | S9: 997.9 | T9: 1082.46 | U9: 788.75 | V9: 810.26 | W9: 846.12 | X9: 917.82
B10: 三相低压储能逆变器 | C10: GW6K-ET-L-G10 | D10: SWH6000L-T1-G2 | E10: 6k | F10: 336 | G10: 6 | H10: 56 | I10: 1227.47 | J10: 1260.95 | K10: 1316.74 | L10: 1428.33 | M10: 1040.77 | N10: 1069.16 | O10: 1116.46 | P10: 1211.08 | Q10: 1286.84 | R10: 1321.94 | S10: 1380.43 | T10: 1497.41 | U10: 1091.11 | V10: 1120.87 | W10: 1170.47 | X10: 1269.66
C11: GW8K-ET-L-G10 | D11: SWH8000L-T1-G2 | E11: 8k | F11: 336 | G11: 6 | H11: 56 | I11: 1250.3 | J11: 1284.4 | K11: 1341.23 | L11: 1454.89 | M11: 1060.13 | N11: 1089.04 | O11: 1137.23 | P11: 1233.6 | Q11: 1310.34 | R11: 1346.08 | S11: 1405.64 | T11: 1524.76 | U11: 1111.04 | V11: 1141.34 | W11: 1191.84 | X11: 1292.85
C12: GW10K-ET-L-G10 | D12: SWH010KL-T1-G2 | E12: 10k | F12: 336 | G12: 6 | H12: 56 | I12: 1298.63 | J12: 1334.05 | K12: 1393.08 | L12: 1511.14 | M12: 1101.11 | N12: 1131.14 | O12: 1181.19 | P12: 1281.29 | Q12: 1360.11 | R12: 1397.2 | S12: 1459.03 | T12: 1582.67 | U12: 1153.24 | V12: 1184.69 | W12: 1237.11 | X12: 1341.95
C13: W12K-ET-L-G10 | D13: SWH012KL-T1-G2 | E13: 12k | F13: 336 | G13: 6 | H13: 56 | I13: 1384.45 | J13: 1422.21 | K13: 1485.14 | L13: 1610.99 | M13: 1173.87 | N13: 1205.89 | O13: 1259.25 | P13: 1365.96 | Q13: 1448.47 | R13: 1487.97 | S13: 1553.81 | T13: 1685.49 | U13: 1228.15 | V13: 1261.65 | W13: 1317.47 | X13: 1429.12
C14: GW15K-ET-L-G10 | D14: SWH015KL-T1-G2 | E14: 15k | F14: 336 | G14: 6 | H14: 56 | I14: 1500.7 | J14: 1541.63 | K14: 1609.84 | L14: 1746.27 | M14: 1272.45 | N14: 1307.15 | O14: 1364.99 | P14: 1480.66 | Q14: 1568.16 | R14: 1610.93 | S14: 1682.21 | T14: 1824.77 | U14: 1329.64 | V14: 1365.91 | W14: 1426.34 | X14: 1547.22
C15: GW20K-ET-L-G10 | D15: SWH020KL-T1-G2 | E15: 20k | F15: 168 | G15: 4 | H15: 42 | I15: 1614.11 | J15: 1658.13 | K15: 1731.5 | L15: 1878.24 | M15: 1368.6 | N15: 1405.93 | O15: 1468.14 | P15: 1592.56 | Q15: 1705.03 | R15: 1751.53 | S15: 1829.03 | T15: 1984.04 | U15: 1445.7 | V15: 1485.12 | W15: 1550.84 | X15: 1682.26
B16: 低压电池（IP65) | C16: LXU 5.0-30 | D16: SWR5.12-L1-GW | E16: 5.12kWh（壁挂/落地） | F16: 384 | G16: 12 | H16: 32 | I16: 859.63 | J16: 883.08 | K16: 922.15 | L16: 1000.3 | M16: 728.88 | N16: 748.76 | O16: 781.89 | P16: 848.15 | Q16: 927.6 | R16: 952.9 | S16: 995.06 | T16: 1079.39 | U16: 786.51 | V16: 807.96 | W16: 843.72 | X16: 915.22
C17: LXU 5.0-30*2 | E17: 10.24kWh | F17: 192 | G17: 6 | H17: 32 | I17: 1719.26 | J17: 1766.15 | K17: 1844.3 | L17: 2000.6 | M17: 1457.76 | N17: 1497.52 | O17: 1563.78 | P17: 1696.31 | Q17: 1855.01 | R17: 1905.6 | S17: 1989.92 | T17: 2158.56 | U17: 1572.86 | V17: 1615.76 | W17: 1687.25 | X17: 1830.24
C18: LXU 5.0-30 | D18: SWR5.12-L1-GW | E18: 5.12kWh（堆叠） | F18: 384 | G18: 12 | H18: 32 | I18: 859.63 | J18: 883.08 | K18: 922.15 | L18: 1000.3 | M18: 728.88 | N18: 748.76 | O18: 781.89 | P18: 848.15 | Q18: 927.6 | R18: 952.9 | S18: 995.06 | T18: 1079.39 | U18: 786.51 | V18: 807.96 | W18: 843.72 | X18: 915.22
B19: 低压电池B(IP20) | C19: LX A5.0-10 | D19: SWR5.12-L2-GR | E19: 5.12kWh（壁挂/落地） | F19: 384 | G19: 12 | H19: 32 | I19: 500.18 | J19: 513.82 | K19: 536.55 | L19: 582.03 | M19: 424.1 | N19: 435.67 | O19: 454.94 | P19: 493.5 | Q19: 547.52 | R19: 562.45 | S19: 587.34 | T19: 637.11 | U19: 464.24 | V19: 476.9 | W19: 498 | X19: 540.2
C20: LX A5.0-10*2 | E20: 10.24kWh | F20: 192 | G20: 6 | H20: 32 | I20: 1000.36 | J20: 1027.64 | K20: 1073.11 | L20: 1164.05 | M20: 848.2 | N20: 871.33 | O20: 909.89 | P20: 987 | Q20: 1094.84 | R20: 1124.7 | S20: 1174.46 | T20: 1273.99 | U20: 928.31 | V20: 953.63 | W20: 995.83 | X20: 1080.22
C21: GW14.3-BAT-LV-G10 | E21: 14.3kWh | F21: 128 | G21: 4 | H21: 32 | I21: 1405.24 | J21: 1443.57 | K21: 1507.44 | L21: 1635.19 | M21: 1191.5 | N21: 1224 | O21: 1278.16 | P21: 1386.48 | Q21: 1541.4 | R21: 1583.44 | S21: 1653.5 | T21: 1793.63 | U21: 1306.95 | V21: 1342.59 | W21: 1402 | X21: 1520.82
B22: 三相高压储能逆变器 | C22: GW30K-ET/GW30K-ET-10（内置STS) | D22: SWH030KH-T1-G2 | E22: 30k | F22: 168 | G22: 4 | H22: 42 | I22: 1760.66 | J22: 1808.68 | K22: 1888.71 | L22: 2048.77 | M22: 1492.86 | N22: 1533.58 | O22: 1601.44 | P22: 1737.15 | Q22: 1855.92 | R22: 1906.53 | S22: 1990.89 | T22: 2159.61 | U22: 1573.63 | V22: 1616.55 | W22: 1688.08 | X22: 1831.14
C23: GW40K-ET-10（STS可选配） | D23: SWH040KH-T1-G2 | E23: 40k | F23: 160 | G23: 4 | H23: 40 | I23: 2117.49 | J23: 2175.24 | K23: 2271.49 | L23: 2463.99 | M23: 1795.42 | N23: 1844.39 | O23: 1926 | P23: 2089.22 | Q23: 2225.05 | R23: 2285.73 | S23: 2386.87 | T23: 2589.15 | U23: 1886.62 | V23: 1938.07 | W23: 2023.83 | X23: 2195.34
C24: GW50K-ET-10（STS可选配） | D24: SWH050KH-T1-G2 | E24: 50k | F24: 160 | G24: 4 | H24: 40 | I24: 2230.79 | J24: 2291.63 | K24: 2393.03 | L24: 2595.82 | M24: 1891.48 | N24: 1943.07 | O24: 2029.05 | P24: 2201 | Q24: 2341.7 | R24: 2405.56 | S24: 2512 | T24: 2724.89 | U24: 1985.53 | V24: 2039.68 | W24: 2129.93 | X24: 2310.43
C25: GW100K-ET G10 | D25: SWH100KH-T1-G2 | E25: 100k | F25: 96 | G25: 1 | H25: 96 | I25: 3136.71 | J25: 3222.26 | K25: 3364.83 | L25: 3649.99 | M25: 2659.62 | N25: 2732.15 | O25: 2853.04 | P25: 3094.83 | Q25: 3325.97 | R25: 3416.68 | S25: 3567.86 | T25: 3870.22 | U25: 2820.09 | V25: 2897 | W25: 3025.19 | X25: 3281.56
B26: 储能电池柜（高压） | C26: GW102.4-BAT-AC-G10/GW112.6-BAT_x0002_AC-G10/（气溶胶） | D26: SWC102.4-H1-GC/SWC112.6-H1-GC | E26: 100kWh | F26: 18 | G26: 1 | H26: 18 | I26: 18551.11 | J26: 19048.02 | K26: 19876.19 | L26: 21532.54 | M26: 15729.49 | N26: 16150.82 | O26: 16853.02 | P26: 18257.44 | Q26: 19988.08 | R26: 20523.48 | S26: 21415.8 | T26: 23200.45 | U26: 16947.89 | V26: 17401.86 | W26: 18158.46 | X26: 19671.66
B27: 三相并网逆变器 | C27: GW80K-SMT/GW80K-SMT | E27: 80k | F27: 172 | G27: 2 | H27: 86 | I27: 1846.81 | J27: 1897.18 | K27: 1981.13 | L27: 2149.02 | M27: 1565.91 | N27: 1608.62 | O27: 1679.8 | P27: 1822.15 | Q27: 1952.02 | R27: 2005.26 | S27: 2093.99 | T27: 2271.44 | U27: 1655.12 | V27: 1700.26 | W27: 1775.49 | X27: 1925.96
C28: GW100K-GT/GW100K-GT | E28: 100k | F28: 96 | G28: 1 | H28: 96 | I28: 2378.31 | J28: 2443.18 | K28: 2551.28 | L28: 2767.49 | M28: 2016.57 | N28: 2071.57 | O28: 2163.23 | P28: 2346.56 | Q28: 2542.53 | R28: 2611.87 | S28: 2727.44 | T28: 2958.58 | U28: 2155.81 | V28: 2214.6 | W28: 2312.6 | X28: 2508.58
C29: GW110K-GT/GW110K-GT | E29: 110K | F29: 96 | G29: 1 | H29: 96 | I29: 2475.68 | J29: 2543.2 | K29: 2655.73 | L29: 2880.8 | M29: 2099.13 | N29: 2156.38 | O29: 2251.8 | P29: 2442.63 | Q29: 2642.78 | R29: 2714.86 | S29: 2834.98 | T29: 3075.24 | U29: 2240.81 | V29: 2301.93 | W29: 2403.78 | X29: 2607.49
C30: GW125K-GT/GW125K-GT | E30: 125kW | F30: 96 | G30: 1 | H30: 96 | I30: 2491.32 | J30: 2559.27 | K30: 2672.51 | L30: 2899 | M30: 2112.39 | N30: 2170.01 | O30: 2266.02 | P30: 2458.06 | Q30: 2664.07 | R30: 2736.73 | S30: 2857.83 | T30: 3100.01 | U30: 2258.87 | V30: 2320.47 | W30: 2423.15 | X30: 2628.5
B31: 并机选配 | C31: SEC3000C | E31: 智能通讯箱 | F31: 276 | G31: 6 | H31: 46 | I31: 537.53 | J31: 552.19 | K31: 576.62 | L31: 625.49 | M31: 455.77 | N31: 468.2 | O31: 488.92 | P31: 530.35 | Q31: 580.25 | R31: 596.08 | S31: 622.45 | T31: 675.2 | U31: 491.99 | V31: 505.41 | W31: 527.78 | X31: 572.5

Sheet 逆变器-10年质保
A1: 产品信息 | G1: 装柜数量 | J1: FOB市场定价$ | N1: FOB市场定价€ | R1: 市场定价欧仓提货价$ | V1: 市场定价欧仓提货价€
A2: 厂家 | B2: 分类 | C2: 物料编码 | D2: 产品型号 | E2: 创维型号 | F2: 规格 | G2: 装柜量 | H2: 单托数量 | I2: 托盘数 | J2: 大型经销商 | K2: 中型经销商 | L2: 中型安装商 | M2: 小型安装商 | N2: 大型经销商 | O2: 中型经销商 | P2: 中型安装商 | Q2: 小型安装商 | R2: 大型经销商 | S2: 中型经销商 | T2: 中型安装商 | U2: 小型安装商 | V2: 大型经销商 | W2: 中型经销商 | X2: 中型安装商 | Y2: 小型安装商
A3: 硕日 | B3: Low voltage Single phase 低压单相逆变器（10年质保） | C3: N036101-000091-001 | D3: SWH3600L-S1-SR | E3: SWH3600L-S1-SR | F3: 3.6kw | G3: 672 | H3: =G3/I3 -> 16 | I3: =G3/16 -> 42 | J3: 532.95 | K3: 552.87 | L3: 572.8 | M3: 622.61 | N3: 454.45 | O3: 471.44 | P3: 488.42 | Q3: 530.9 | R3: 396.47 | S3: 411.29 | T3: 426.11 | U3: 463.17 | V3: 464.96 | W3: 482.34 | X3: 499.72 | Y3: 543.18
C4: N036101-000092-001 | D4: SWH4000L-S1-SR | E4: SWH4000L-S1-SR | F4: 4kw | G4: 672 | H4: =G4/I4 -> 16 | I4: =G4/16 -> 42 | J4: 532.95 | K4: 552.87 | L4: 572.8 | M4: 622.61 | N4: 454.45 | O4: 471.44 | P4: 488.42 | Q4: 530.9 | R4: 396.47 | S4: 411.29 | T4: 426.11 | U4: 463.17 | V4: 464.96 | W4: 482.34 | X4: 499.72 | Y4: 543.18
C5: N036101-000006-005 | D5: SWH5000L-S1-SR | E5: SWH5000L-S1-SR | F5: 5kw | G5: 672 | H5: =G5/I5 -> 16 | I5: =G5/16 -> 42 | J5: 532.95 | K5: 552.87 | L5: 572.8 | M5: 622.61 | N5: 454.45 | O5: 471.44 | P5: 488.42 | Q5: 530.9 | R5: 396.47 | S5: 411.29 | T5: 426.11 | U5: 463.17 | V5: 464.96 | W5: 482.34 | X5: 499.72 | Y5: 543.18
C6: N036101-000017-003 | D6: SWH6000L-S1-SR | E6: SWH6000L-S1-SR | F6: 6kw | G6: 672 | H6: =G6/I6 -> 16 | I6: =G6/16 -> 42 | J6: 532.95 | K6: 552.87 | L6: 572.8 | M6: 622.61 | N6: 454.45 | O6: 471.44 | P6: 488.42 | Q6: 530.9 | R6: 396.47 | S6: 411.29 | T6: 426.11 | U6: 463.17 | V6: 464.96 | W6: 482.34 | X6: 499.72 | Y6: 543.18
C7: N036101-000007-004 | D7: SWH008KL-S1-SR | E7: SWH008KL-S1-SR | F7: 8kw | G7: 252 | H7: =G7/I7 -> 12 | I7: =G7/12 -> 21 | J7: 1112.09 | K7: 1153.67 | L7: 1195.24 | M7: 1299.17 | N7: 948.28 | O7: 983.73 | P7: 1019.18 | Q7: 1107.81 | R7: 829.03 | S7: 860.02 | T7: 891.02 | U7: 968.5 | V7: 972.24 | W7: 1008.59 | X7: 1044.94 | Y7: 1135.8
C8: N036101-000008-007 | D8: SWH010KL-S1-SR | E8: SWH010KL-S1-SR | F8: 10kw | G8: 252 | H8: =G8/I8 -> 12 | I8: =G8/12 -> 21 | J8: 1112.09 | K8: 1153.67 | L8: 1195.24 | M8: 1299.17 | N8: 948.28 | O8: 983.73 | P8: 1019.18 | Q8: 1107.81 | R8: 829.03 | S8: 860.02 | T8: 891.02 | U8: 968.5 | V8: 972.24 | W8: 1008.59 | X8: 1044.94 | Y8: 1135.8
C9: N036101-000016-003 | D9: SWH012KL-S1-SR | E9: SWH012KL-S1-SR | F9: 12kw | G9: 252 | H9: =G9/I9 -> 12 | I9: =G9/12 -> 21 | J9: 1112.09 | K9: 1153.67 | L9: 1195.24 | M9: 1299.17 | N9: 948.28 | O9: 983.73 | P9: 1019.18 | Q9: 1107.81 | R9: 829.03 | S9: 860.02 | T9: 891.02 | U9: 968.5 | V9: 972.24 | W9: 1008.59 | X9: 1044.94 | Y9: 1135.8
B10: 三相低压逆变器（10年质保） | D10: SPI-8K-H3P | E10: SPI-8K-H3P | F10: 8kw | G10: 322 | H10: =G10/I10 -> 7 | I10: 46 | J10: 1126.79 | K10: 1168.91 | L10: 1211.03 | M10: 1316.34 | N10: 960.81 | O10: 996.73 | P10: 1032.65 | Q10: 1122.44 | R10: 838.19 | S10: 869.52 | T10: 900.86 | U10: 979.19 | V10: 982.98 | W10: 1019.73 | X10: 1056.48 | Y10: 1148.34
D11: SPI-10K-H4P | E11: SPI-10K-H4P | F11: 10kw | G11: 322 | H11: =G11/I11 -> 7 | I11: 46 | J11: 1126.79 | K11: 1168.91 | L11: 1211.03 | M11: 1316.34 | N11: 960.81 | O11: 996.73 | P11: 1032.65 | Q11: 1122.44 | R11: 838.19 | S11: 869.52 | T11: 900.86 | U11: 979.19 | V11: 982.98 | W11: 1019.73 | X11: 1056.48 | Y11: 1148.34
D12: SPI-12K-H5P | E12: SPI-12K-H5P | F12: 12kw | G12: 322 | H12: =G12/I12 -> 7 | I12: 46 | J12: 1126.79 | K12: 1168.91 | L12: 1211.03 | M12: 1316.34 | N12: 960.81 | O12: 996.73 | P12: 1032.65 | Q12: 1122.44 | R12: 838.19 | S12: 869.52 | T12: 900.86 | U12: 979.19 | V12: 982.98 | W12: 1019.73 | X12: 1056.48 | Y12: 1148.34
A13: 固德威（欧洲） | B13: 单相低压储能逆变器（10年质保） | D13: GW3000-ES-20 | E13: SWH3000L-S2-G2 | F13: 3KW | G13: 336 | H13: 6 | I13: =G13/H13 -> 56 | J13: 718.58 | K13: 738.18 | L13: 770.84 | M13: 836.17 | N13: 612.74 | O13: 629.45 | P13: 657.3 | Q13: 713 | R13: 540.15 | S13: 554.88 | T13: 579.43 | U13: 628.54 | V13: 633.46 | W13: 650.73 | X13: 679.53 | Y13: 737.12
D14: GW3600-ES-20 | E14: SWH3600L-S2-G2 | F14: 3.6kW | G14: 336 | H14: 6 | I14: =G14/H14 -> 56 | J14: 796.19 | K14: 817.91 | L14: 854.1 | M14: 926.48 | N14: 678.91 | O14: 697.43 | P14: 728.29 | Q14: 790.01 | R14: 596.91 | S14: 613.19 | T14: 640.32 | U14: 694.59 | V14: 700.02 | W14: 719.11 | X14: 750.93 | Y14: 814.57
D15: GW5000-ES-20 | E15: SWH5000L-S2-G2 | F15: 5KW | G15: 336 | H15: 6 | I15: =G15/H15 -> 56 | J15: 827.24 | K15: 849.8 | L15: 887.4 | M15: 962.6 | N15: 705.38 | O15: 724.62 | P15: 756.68 | Q15: 820.81 | R15: 619.61 | S15: 636.51 | T15: 664.68 | U15: 721 | V15: 726.65 | W15: 746.47 | X15: 779.5 | Y15: 845.56
D16: GW6000-ES-20 | E16: SWH6000L-S2-G2 | F16: 6k | G16: 336 | H16: 6 | I16: =G16/H16 -> 56 | J16: 841.78 | K16: 864.73 | L16: 903 | M16: 979.52 | N16: 717.78 | O16: 737.36 | P16: 769.99 | Q16: 835.24 | R16: 630.25 | S16: 647.44 | T16: 676.08 | U16: 733.38 | V16: 739.12 | W16: 759.28 | X16: 792.88 | Y16: 860.07
B17: 三相高压储能逆变器（10年质保） | D17: GW6000-ET-20 | E17: SWH6000H-T1-G2 | F17: 5k | G17: 336 | H17: 6 | I17: =G17/H17 -> 56 | J17: 1164.96 | K17: 1196.73 | L17: 1249.68 | M17: 1355.59 | N17: 993.36 | O17: 1020.45 | P17: 1065.6 | Q17: 1155.91 | R17: 864.64 | S17: 888.22 | T17: 927.52 | U17: 1006.13 | V17: 1014 | W17: 1041.66 | X17: 1087.75 | Y17: 1179.93
D18: GW8000-ET-20 | E18: SWH8000H-T1-G2 | F18: 8k | G18: 336 | H18: 6 | I18: =G18/H18 -> 56 | J18: 1189.14 | K18: 1221.57 | L18: 1275.62 | M18: 1383.73 | N18: 1013.98 | O18: 1041.63 | P18: 1087.72 | Q18: 1179.9 | R18: 882.32 | S18: 906.39 | T18: 946.49 | U18: 1026.7 | V18: 1034.74 | W18: 1062.96 | X18: 1110 | Y18: 1204.06
D19: GW10K-ET-20 | E19: SWH010KH-T1-G2 | F19: 10k | G19: 336 | H19: 6 | I19: =G19/H19 -> 56 | J19: 1225.74 | K19: 1259.17 | L19: 1314.88 | M19: 1426.31 | N19: 1045.19 | O19: 1073.69 | P19: 1121.2 | Q19: 1216.22 | R19: 912.97 | S19: 937.87 | T19: 979.37 | U19: 1062.37 | V19: 1070.69 | W19: 1099.89 | X19: 1148.55 | Y19: 1245.89
D20: GW12K-ET-20 | E20: SWH012KH-T1-G2 | F20: 12k | G20: 336 | H20: 6 | I20: =G20/H20 -> 56 | J20: 1240.77 | K20: 1274.61 | L20: 1331.01 | M20: 1443.8 | N20: 1058 | O20: 1086.86 | P20: 1134.95 | Q20: 1231.13 | R20: 923.97 | S20: 949.17 | T20: 991.17 | U20: 1075.16 | V20: 1083.58 | W20: 1113.13 | X20: 1162.38 | Y20: 1260.89
D21: GW15K-ET-20 | E21: SWH015KH-T1-G2 | F21: 15k | G21: 336 | H21: 6 | I21: =G21/H21 -> 56 | J21: 1254.33 | K21: 1288.54 | L21: 1345.55 | M21: 1459.58 | N21: 1069.57 | O21: 1098.74 | P21: 1147.35 | Q21: 1244.59 | R21: 933.89 | S21: 959.36 | T21: 1001.8 | U21: 1086.7 | V21: 1095.21 | W21: 1125.08 | X21: 1174.86 | Y21: 1274.43
D22: GW20K-ET | E22: SWH020KH-T1-G2 | F22: 20k | G22: 168 | H22: 4 | I22: =G22/H22 -> 42 | J22: 2412.1 | K22: 2477.88 | L22: 2587.52 | M22: 2806.8 | N22: 2056.8 | O22: 2112.89 | P22: 2206.38 | Q22: 2393.36 | R22: 1795.03 | S22: 1843.99 | T22: 1925.58 | U22: 2088.77 | V22: 2105.12 | W22: 2162.53 | X22: 2258.22 | Y22: 2449.59
B23: 三相高压储能逆变器（10年质保） | D23: GW30K-ET/GW30K-ET-10（内置STS) | E23: SWH030KH-T1-G2 | F23: 30k | G23: 168 | H23: 4 | I23: =G23/H23 -> 42 | J23: 2743.61 | K23: 2818.44 | L23: 2943.15 | M23: 3192.57 | N23: 2339.48 | O23: 2403.28 | P23: 2509.62 | Q23: 2722.3 | R23: 2037.49 | S23: 2093.05 | T23: 2185.67 | U23: 2370.89 | V23: 2389.45 | W23: 2454.62 | X23: 2563.23 | Y23: 2780.45
D24: GW40K-ET-10（STS可选配） | E24: SWH040KH-T1-G2 | F24: 40k | G24: 160 | H24: 4 | I24: =G24/H24 -> 40 | J24: 2963.06 | K24: 3043.87 | L24: 3178.55 | M24: 3447.92 | N24: 2526.6 | O24: 2595.51 | P24: 2710.35 | Q24: 2940.04 | R24: 2199.22 | S24: 2259.2 | T24: 2359.16 | U24: 2559.09 | V24: 2579.13 | W24: 2649.47 | X24: 2766.7 | Y24: 3001.17
D25: GW50K-ET-10（STS可选配） | E25: SWH050KH-T1-G2 | F25: 50k | G25: 160 | H25: 4 | I25: =G25/H25 -> 40 | J25: 3121.71 | K25: 3206.84 | L25: 3348.74 | M25: 3632.53 | N25: 2661.88 | O25: 2734.48 | P25: 2855.47 | Q25: 3097.46 | R25: 2315.25 | S25: 2378.39 | T25: 2483.63 | U25: 2694.11 | V25: 2715.2 | W25: 2789.25 | X25: 2912.67 | Y25: 3159.5
D26: GW100K-ET-G10 | E26: SWH100KH-T1-G2 | F26: 100k | G26: 96 | H26: 1 | I26: =G26/H26 -> 96 | J26: 4447.83 | K26: 4569.13 | L26: 4771.31 | M26: 5175.66 | N26: 3792.66 | O26: 3896.1 | P26: 4068.5 | Q26: 4413.28 | R26: 3322.19 | S26: 3412.8 | T26: 3563.81 | U26: 3865.83 | V26: 3896.09 | W26: 4002.34 | X26: 4179.44 | Y26: 4533.63
B27: 三相并网逆变器（10年质保） | D27: GW80K-SMT/GW80K-SMT | E27: SW100KTL-T1-G2 | F27: 80k | G27: 172 | H27: 2 | I27: =G27/H27 -> 86 | J27: 2702.68 | K27: 2776.39 | L27: 2899.24 | M27: 3144.94 | N27: 2304.58 | O27: 2367.43 | P27: 2472.18 | Q27: 2681.69 | R27: 2012.91 | S27: 2067.8 | T27: 2159.3 | U27: 2342.29 | V27: 2360.63 | W27: 2425.01 | X27: 2532.31 | Y27: 2746.91
D28: GW100K-GT/GW100K-GT | E28: SW100KTL-T1-G2 | F28: 100k | G28: 96 | H28: 1 | I28: =G28/H28 -> 96 | J28: 3479.43 | K28: 3574.33 | L28: 3732.48 | M28: 4048.8 | N28: 2966.91 | O28: 3047.83 | P28: 3182.69 | Q28: 3452.41 | R28: 2612.08 | S28: 2683.32 | T28: 2802.05 | U28: 3039.51 | V28: 3063.3 | W28: 3146.85 | X28: 3286.09 | Y28: 3564.57
D29: GW110K-GT/GW110K-GT | E29: SW110KTL-T1-G2 | F29: 110K | G29: 96 | H29: 1 | I29: =G29/H29 -> 96 | J29: 3622.07 | K29: 3720.86 | L29: 3885.49 | M29: 4214.77 | N29: 3088.54 | O29: 3172.77 | P29: 3313.16 | Q29: 3593.94 | R29: 2716.4 | S29: 2790.48 | T29: 2913.95 | U29: 3160.9 | V29: 3185.64 | W29: 3272.52 | X29: 3417.32 | Y29: 3706.93
D30: GW125K-GT/GW125K-GT | E30: SW125KTL-T1-G2 | F30: 125kW | G30: 96 | H30: 1 | I30: =G30/H30 -> 96 | J30: 3644.95 | K30: 3744.35 | L30: 3910.03 | M30: 4241.39 | N30: 3108.05 | O30: 3192.81 | P30: 3334.08 | Q30: 3616.63 | R30: 2733.13 | S30: 2807.66 | T30: 2931.9 | U30: 3180.36 | V30: 3205.26 | W30: 3292.68 | X30: 3438.37 | Y30: 3729.76
A31: 固德威（东南亚） | B31: 单相低压储能逆变器（10年质保） | D31: GW3000-ES-C10 | E31: SWH3000L-S1-G2 | F31: 3KW | G31: 336 | H31: 6 | I31: =G31/H31 -> 56 | J31: 553.73 | K31: 568.83 | L31: 594 | M31: 644.34 | N31: 472.16 | O31: 485.04 | P31: 506.5 | Q31: 549.42 | R31: 421.5 | S31: 432.99 | T31: 452.15 | U31: 490.47 | V31: 494.31 | W31: 507.79 | X31: 530.26 | Y31: 575.19
D32: GW3600-ES-C10 | E32: SWH3600L-S1-G2 | F32: 3.6kW | G32: 336 | H32: 6 | I32: =G32/H32 -> 56 | J32: 609.11 | K32: 625.73 | L32: 653.41 | M32: 708.79 | N32: 519.39 | O32: 533.56 | P32: 557.17 | Q32: 604.38 | R32: 462 | S32: 474.6 | T32: 495.6 | U32: 537.61 | V32: 541.81 | W32: 556.59 | X32: 581.22 | Y32: 630.47
D33: GW5000-ES-C10 | E33: SWH5000L-S1-G2 | F33: 5KW | G33: 336 | H33: 6 | I33: =G33/H33 -> 56 | J33: 637.38 | K33: 654.76 | L33: 683.73 | M33: 741.68 | N33: 543.49 | O33: 558.32 | P33: 583.02 | Q33: 632.43 | R33: 482.68 | S33: 495.84 | T33: 517.78 | U33: 561.66 | V33: 566.06 | W33: 581.5 | X33: 607.23 | Y33: 658.68
D34: GW6000-ES-C10 | E34: SWH6000L-S1-G2 | F34: 6k | G34: 336 | H34: 6 | I34: =G34/H34 -> 56 | J34: 660.91 | K34: 678.93 | L34: 708.97 | M34: 769.06 | N34: 563.56 | O34: 578.93 | P34: 604.54 | Q34: 655.77 | R34: 499.88 | S34: 513.52 | T34: 536.24 | U34: 581.68 | V34: 586.24 | W34: 602.23 | X34: 628.87 | Y34: 682.17
D35: GW8000-ES-C10 | E35: SWH8000L-S1-G2 | F35: 8k | G35: 384 | H35: 12 | I35: =G35/H35 -> 32 | J35: 855.44 | K35: 878.77 | L35: 917.65 | M35: 995.42 | N35: 729.43 | O35: 749.33 | P35: 782.48 | Q35: 848.8 | R35: 638.62 | S35: 656.04 | T35: 685.07 | U35: 743.13 | V35: 748.94 | W35: 769.37 | X35: 803.41 | Y35: 871.5
D36: GW10K-ES-C10 | E36: SWH010KL-S1-G2 | F36: 10k | G36: =G35/2 -> 192 | H36: 6 | I36: =G36/H36 -> 32 | J36: 980.54 | K36: 1007.28 | L36: 1051.85 | M36: 1140.99 | N36: 836.11 | O36: 858.91 | P36: 896.91 | Q36: 972.92 | R36: 742.97 | S36: 763.23 | T36: 797.01 | U36: 864.55 | V36: 871.32 | W36: 895.08 | X36: 934.68 | Y36: 1013.89
D37: GW12K-ES-C10 | E37: SWH012KL-S1-G2 | F37: 12k | G37: 264 | H37: 6 | I37: =G37/H37 -> 44 | J37: 1015.95 | K37: 1043.66 | L37: 1089.84 | M37: 1182.2 | N37: 866.3 | O37: 889.93 | P37: 929.3 | Q37: 1008.06 | R37: 762.94 | S37: 783.74 | T37: 818.42 | U37: 887.78 | V37: 894.73 | W37: 919.13 | X37: 959.8 | Y37: 1041.14
B38: 三相低压储能逆变器（10年质保） | D38: GW6K-ET-L-G10 | E38: SWH6000L-T1-G2 | F38: 6k | G38: 336 | H38: 6 | I38: =G38/H38 -> 56 | J38: 1422.95 | K38: 1461.75 | L38: 1526.43 | M38: 1655.79 | N38: 1213.35 | O38: 1246.44 | P38: 1301.59 | Q38: 1411.89 | R38: 1057.2 | S38: 1086.04 | T38: 1134.09 | U38: 1230.2 | V38: 1239.83 | W38: 1273.64 | X38: 1330 | Y38: 1442.71
D39: GW8K-ET-L-G10 | E39: SWH8000L-T1-G2 | F39: 8k | G39: 336 | H39: 6 | I39: =G39/H39 -> 56 | J39: 1449.41 | K39: 1488.94 | L39: 1554.83 | M39: 1686.59 | N39: 1235.92 | O39: 1269.62 | P39: 1325.8 | Q39: 1438.16 | R39: 1076.56 | S39: 1105.92 | T39: 1154.86 | U39: 1252.73 | V39: 1262.53 | W39: 1296.97 | X39: 1354.35 | Y39: 1469.13
D40: GW10K-ET-L-G10 | E40: SWH010KL-T1-G2 | F40: 10k | G40: 336 | H40: 6 | I40: =G40/H40 -> 56 | J40: 1505.46 | K40: 1546.51 | L40: 1614.94 | M40: 1751.8 | N40: 1283.7 | O40: 1318.71 | P40: 1377.06 | Q40: 1493.76 | R40: 1117.55 | S40: 1148.03 | T40: 1198.82 | U40: 1300.42 | V40: 1310.6 | W40: 1346.34 | X40: 1405.92 | Y40: 1525.06
...

Sheet 东南亚仓组件
A1: 国家 | B1: SKU | C1: 分类 | D1: 型号 | E1: 本地自提定价（EXW）$/PCS | H1: 本地自提定价（EXW）＄/W
E2: 整柜 | F2: 整托 | G2: 不成整托 | H2: 整柜 | I2: 整托 | J2: 不成整托
A3: 泰国 | B3: N036001-000707-000 | C3: 组件 | D3: 620--广州高景 | E3: 78.18 | F3: 81.94 | G3: 87.95 | H3: 0.126 | I3: 0.132 | J3: 0.142
A4: 泰国 | B4: QM210THCD-625-66 | C4: 组件 | D4: QM210THCD-625-66 | E4: 78.79 | F4: 82.58 | G4: 88.64 | H4: 0.126 | I4: 0.132 | J4: 0.142
A5: 泰国 | B5: 660--珠海爱旭 | C5: 组件 | D5: 660--珠海爱旭 | E5: 85.25 | F5: 90.08 | G5: 98.12 | H5: 0.129 | I5: 0.136 | J5: 0.149
A6: 国家 | B6: SKU | C6: 分类 | D6: 型号 | E6: 本地自提定价（DAP）$/PCS | H6: 本地自提定价（DAP）＄/W
E7: 整柜 | F7: 整托 | G7: 不成整托 | H7: 整柜 | I7: 整托 | J7: 不成整托
A8: 越南 | B8: N036001-000707-000 | C8: 组件 | D8: 620--广州高景 | E8: 73.91 | F8: 77.47 | G8: 83.15 | H8: 0.119 | I8: 0.125 | J8: 0.134
A9: 越南 | B9: 660--珠海爱旭 | C9: 组件 | D9: 660--珠海爱旭 | E9: 80.44 | F9: 85 | G9: 92.58 | H9: 0.122 | I9: 0.129 | J9: 0.14
A10: 国家 | B10: SKU | C10: 分类 | D10: 型号 | E10: 本地自提定价（DAP）$/PCS | H10: 本地自提定价（DAP）＄/W
E11: 整柜 | F11: 整托 | G11: 不成整托 | H11: 整柜 | I11: 整托 | J11: 不成整托
A12: 马来西亚 | B12: N036001-000707-000 | C12: 组件 | D12: 620--广州高景 | E12: 73.55 | F12: 77.09 | G12: 82.75 | H12: 0.119 | I12: 0.124 | J12: 0.133
A13: 马来西亚 | B13: 660--珠海爱旭 | C13: 组件 | D13: 660--珠海爱旭 | E13: 80.17 | F13: 84.71 | G13: 92.27 | H13: 0.121 | I13: 0.128 | J13: 0.14

Sheet 东南亚仓逆变器
A1: 国家 | B1: SKU | C1: 分类 | D1: 型号 | E1: 本地自提定价（EXW）$
E2: 大型经销商 | F2: 中型经销商 | G2: 中型安装商 | H2: 小型安装商
A3: 泰国 | B3: N036101-000201-002 | C3: 并网逆变器 | D3: GW5K-DNS-G40 | E3: 369.12 | F3: 382.92 | G3: 396.71 | H3: 431.21
A4: 泰国 | B4: N046002-000463-000 | C4: 电表 | D4: GMK110 | E4: 29.47 | F4: 30.57 | G4: 31.67 | H4: 34.43
A5: 泰国 | B5: N036101-000253-001 | C5: 储能逆变器 | D5: GW5000-ES-C10 | E5: 710.42 | F5: 736.98 | G5: 763.54 | H5: 829.93
A6: 泰国 | B6: N030502-000055-000 | C6: 电池 | D6: LX A5.0-10 | E6: 603.1 | F6: 625.65 | G6: 648.19 | H6: 704.56
A7: 泰国 | B7: N036101-000255-001 | C7: 储能逆变器 | D7: GW15K-ET-L-G10 | E7: 1927.32 | F7: 1999.37 | G7: 2071.42 | H7: 2251.54
A8: 泰国 | B8: N030502-000056-000 | C8: 电池 | D8: GW14.3-BAT-LV-G10 | E8: 1578.16 | F8: 1637.15 | G8: 1696.15 | H8: 1843.64
A9: 泰国 | B9: N036101-000254-001 | C9: 储能逆变器 | D9: GW10K-ES-C10 | E9: 1094.46 | F9: 1135.37 | G9: 1176.29 | H9: 1278.57
A10: 国家 | B10: SKU | C10: 分类 | D10: 型号 | E10: 本地自提定价（DAP）$/PCS
E11: 大型经销商 | F11: 中型经销商 | G11: 中型安装商 | H11: 小型安装商
A12: 越南 | B12: N036101-000201-002 | C12: 并网逆变器 | D12: GW5K-DNS-G40 | E12: 329.24 | F12: 341.55 | G12: 353.86 | H12: 384.63
A13: 越南 | B13: N046002-000463-000 | C13: 电表 | D13: GMK110 | E13: 26.3 | F13: 27.28 | G13: 28.26 | H13: 30.72
A14: 越南 | B14: N036101-000253-001 | C14: 储能逆变器 | D14: GW5000-ES-C10 | E14: 634.16 | F14: 657.87 | G14: 681.58 | H14: 740.84
A15: 越南 | B15: N030502-000055-000 | C15: 电池 | D15: LX A5.0-10 | E15: 538.5 | F15: 558.63 | G15: 578.76 | H15: 629.09
A16: 越南 | B16: N036101-000255-001 | C16: 储能逆变器 | D16: GW15K-ET-L-G10 | E16: 1717.29 | F16: 1781.49 | G16: 1845.69 | H16: 2006.18
A17: 越南 | B17: N030502-000056-000 | C17: 电池 | D17: GW14.3-BAT-LV-G10 | E17: 1409.77 | F17: 1462.47 | G17: 1515.17 | H17: 1646.92
A18: 越南 | B18: N036101-000254-001 | C18: 储能逆变器 | D18: GW10K-ES-C10 | E18: 977.36 | F18: 1013.9 | G18: 1050.43 | H18: 1141.78
A19: 国家 | B19: SKU | C19: 分类 | D19: 型号 | E19: 本地自提定价（DAP）$/PCS
E20: 大型经销商 | F20: 中型经销商 | G20: 中型安装商 | H20: 小型安装商
A21: 马来西亚 | B21: N036101-000201-002 | C21: 并网逆变器 | D21: GW5K-DNS-G40 | E21: 329 | F21: 341.3 | G21: 353.6 | H21: 384.34
A22: 马来西亚 | B22: N046002-000463-000 | C22: 电表 | D22: GMK110 | E22: 26.27 | F22: 27.25 | G22: 28.24 | H22: 30.69
A23: 马来西亚 | B23: N036101-000253-001 | C23: 储能逆变器 | D23: GW5000-ES-C10 | E23: 633.53 | F23: 657.21 | G23: 680.89 | H23: 740.1
A24: 马来西亚 | B24: N030502-000055-000 | C24: 电池 | D24: LX A5.0-10 | E24: 537.94 | F24: 558.05 | G24: 578.17 | H24: 628.44
A25: 马来西亚 | B25: N036101-000255-001 | C25: 储能逆变器 | D25: GW15K-ET-L-G10 | E25: 1716.66 | F25: 1780.83 | G25: 1845.01 | H25: 2005.44
A26: 马来西亚 | B26: N030502-000056-000 | C26: 电池 | D26: GW14.3-BAT-LV-G10 | E26: 1408.1 | F26: 1460.74 | G26: 1513.38 | H26: 1644.97
A27: 马来西亚 | B27: N036101-000254-001 | C27: 储能逆变器 | D27: GW10K-ES-C10 | E27: 976.25 | F27: 1012.74 | G27: 1049.24 | H27: 1140.47

Sheet FOB组件参考价（东南亚）
A1: 产品信息 | E1: 装箱情况 | H1: FOB参考价$/PCS | K1: FOB参考价$/W
A2: 产品型号 | B2: 规格 | C2: 功率 | D2: 组件类型 | E2: 装柜量 | F2: 单托数量 | G2: 托盘数 | H2: 整柜 | I2: 整托 | J2: 不成整托 | K2: 整柜 | L2: 整托 | M2: 不成整托
A3: QM210THCD-48 | B3: 450W | C3: 450 | D3: TOPCON全黑 QM210THCD450-48 | E3: 936 | F3: 36 | G3: 26 | H3: 57.99 | I3: 60.78 | J3: 65.24 | K3: 0.129 | L3: 0.135 | M3: 0.145
A4: QM210THCD-60 | B4: 500W | C4: 500 | D4: TOPCON全黑 QM210THCD450-49 1.2米线 | E4: 864 | F4: 36 | G4: 24 | H4: 60.62 | I4: 63.53 | J4: 68.2 | K4: 0.121 | L4: 0.127 | M4: 0.136
A5: QM210THCD-60 | B5: 500W | C5: 500 | D5: TOPCON全黑 QM210THCD450-49 2.4米线 | E5: 864 | F5: 36 | G5: 24 | H5: 62.14 | I5: 65.12 | J5: 69.9 | K5: 0.124 | L5: 0.13 | M5: 0.14
A6: QM210THCD-66 | B6: 615-630W | C6: 620 | D6: TOPCON | E6: 720 | F6: 36 | G6: 20 | H6: 68.08 | I6: 71.36 | J6: 76.59 | K6: 0.11 | L6: 0.115 | M6: 0.124
A7: QM210AHCD-66(BC) | B7: 655W | C7: 655 | D7: BC | E7: 720 | F7: 36 | G7: 20 | H7: 86.94 | I7: 91.87 | J7: 100.07 | K7: 0.133 | L7: 0.14 | M7: 0.153
A8: QM210AHCD-66(BC) | B8: 660W | C8: 660 | D8: BC | E8: 720 | F8: 36 | G8: 20 | H8: 87.6 | I8: 92.56 | J8: 100.82 | K8: 0.133 | L8: 0.14 | M8: 0.153
A9: QM210THCD-66 | B9: 710-720W | C9: 715 | D9: TOPCON | E9: 594 | F9: 33 | G9: 18 | H9: 79.87 | I9: 83.7 | J9: 89.85 | K9: 0.112 | L9: 0.117 | M9: 0.126
A10: QM210THCD-66 | B10: 710-720W | C10: 720 | D10: TOPCON | E10: 594 | F10: 33 | G10: 18 | H10: 79.32 | I10: 83.14 | J10: 89.24 | K10: 0.11 | L10: 0.115 | M10: 0.124

Sheet 阳台光伏(东南亚)
A1: 泰国
A2: 价格测算 | B2: 组件选型 | C2: FOB价格 /CNY | D2: FOB价格 /＄ | E2: 经销商本地价格 RMB | F2: 经销商本地价格 THB | G2: 本地零售价 THB
A3: 一拖二 | B3: 450 | C3: 2850 | D3: =C3/汇率!$B$2 -> 415.28239 | E3: 2999 | F3: 13360 | G3: 17815
A4: 一拖四 | B4: 450 | C4: 5150 | D4: =C4/汇率!$B$2 -> 750.42257 | E4: 5499 | F4: 24499 | G4: 31800
A6: 越南
A7: 价格测算 | B7: 组件选型 | C7: FOB价格 /CNY | D7: FOB价格 /＄ | E7: 经销商本地价格 RMB | F7: 经销商本地价格VND | G7: 本地零售价VND
A8: 一拖二 | B8: 450 | C8: 3099 | D8: =C8/汇率!$B$2 -> 451.56496 | E8: 3399 | F8: 12800000 | G8: 1660000
A9: 一拖四 | B9: 450 | C9: 5799 | D9: =C9/汇率!$B$2 -> 844.99038 | E9: 6499 | F9: 24500000 | G9: 30000000
A11: 马来西亚
A12: 价格测算 | B12: 组件选型 | C12: FOB价格 /CNY | D12: FOB价格 /＄ | E12: 经销商本地价格 RMB | F12: 经销商本地价格MYR | G12: 本地零售价MYR
A13: 一拖二 | B13: 450 | C13: 3099 | D13: =C13/汇率!$B$2 -> 451.56496 | E13: 3399 | F13: 1999 | G13: 2559
A14: 一拖四 | B14: 450 | C14: 5799 | D14: =C14/汇率!$B$2 -> 844.99038 | E14: 6499 | F14: 3799 | G14: 4699

Sheet 客户类型定义
A1: 客户类型 | B1: 客户类型定义 | C1: MOQ
A2: 大型经销商 | B2: 年度一千万以上 | C2: 整柜
A3: 中型经销商 | B3: 年度五百万以上 | C3: 整柜或一百万以上
A4: 中型安装商 | C4: 整托及以上
A5: 小型安装商 | C5: /
